=================================================================================== slowest 10 durations ===================================================================================
4.35s setup    tests/test_feedback_system.py::TestFeedbackSystemIntegration::test_concurrent_feedback_submission
4.04s setup    tests/test_feedback_system.py::TestUserFeedbackProcessor::test_validate_feedback_valid
3.92s setup    tests/test_feedback_system.py::TestUserFeedbackProcessor::test_should_trigger_retrain_threshold
3.92s setup    tests/test_feedback_system.py::TestFeedbackSystemIntegration::test_config_integration
3.73s setup    tests/test_feedback_system.py::TestUserFeedbackProcessor::test_feedback_to_training_example_false_positive
3.63s setup    tests/test_training_data_collector.py::TestTrainingDataCollector::test_collect_all_training_data_with_examples_in_storage
3.62s setup    tests/test_feedback_system.py::TestUserFeedbackProcessor::test_validate_feedback_invalid
3.59s setup    tests/test_feedback_system.py::TestUserFeedbackProcessor::test_get_feedback_stats
3.46s setup    tests/test_feedback_system.py::TestUserFeedbackProcessor::test_feedback_to_training_example_false_negative
3.45s setup    tests/test_feedback_system.py::TestUserFeedbackProcessor::test_submit_feedback
================================================================================= short test summary info ==================================================================================
ERROR tests/test_ml_integration_layer.py::TestMLIntegrationLayerFeedback::test_add_user_feedback_confirmed_correct - NameError: name 'MockCoordinator' is not defined
ERROR tests/test_ml_integration_layer.py::TestMLIntegrationLayerFeedback::test_add_user_feedback_false_positive - NameError: name 'MockCoordinator' is not defined
ERROR tests/test_ml_integration_layer.py::TestMLIntegrationLayerFeedback::test_add_user_feedback_category_correction - NameError: name 'MockCoordinator' is not defined
ERROR tests/test_ml_integration_layer.py::TestMLIntegrationLayerFeedback::test_add_user_feedback_context_details - NameError: name 'MockCoordinator' is not defined
ERROR tests/test_ml_integration_layer.py::TestMLIntegrationLayerFeedback::test_add_user_feedback_handles_uuid - NameError: name 'MockCoordinator' is not defined
ERROR tests/test_ml_integration_layer.py::TestMLIntegrationLayerFeedback::test_add_user_feedback_handles_user_feedback_system_failure - NameError: name 'MockCoordinator' is not defined
ERROR tests/test_ml_integration_layer.py::TestMLIntegrationLayerDetectionProcessing::test_detect_with_ml_integration_calls_quality_analyzer - NameError: name 'MockCoordinator' is not defined
ERROR tests/test_ml_integration_layer.py::TestMLIntegrationLayerDetectionProcessing::test_detect_with_ml_integration_calls_quality_analyzer_on_fallback - NameError: name 'MockCoordinator' is not defined
ERROR tests/test_ml_integration_layer.py::TestMLConfidenceScorerIntegration::test_adaptive_pattern_overrides_ml_model - NameError: name 'MockCoordinator' is not defined
ERROR tests/test_morning_ses5_improvements.py::TestMorningSes5AntiOverredaction::test_preserve_detection_technical_terms - AttributeError: 'module' object at app.services.pdf_processor has no attribute 'get_config'
ERROR tests/test_morning_ses5_improvements.py::TestMorningSes5AntiOverredaction::test_preserve_detection_technical_sections - AttributeError: 'module' object at app.services.pdf_processor has no attribute 'get_config'
ERROR tests/test_morning_ses5_improvements.py::TestMorningSes5AntiOverredaction::test_no_preserve_pii_in_technical_sections - AttributeError: 'module' object at app.services.pdf_processor has no attribute 'get_config'
ERROR tests/test_morning_ses5_improvements.py::TestMorningSes5AntiOverredaction::test_preserve_detection_technical_indicators - AttributeError: 'module' object at app.services.pdf_processor has no attribute 'get_config'
ERROR tests/test_morning_ses5_improvements.py::TestMorningSes5AntiOverredaction::test_no_preserve_regular_detections - AttributeError: 'module' object at app.services.pdf_processor has no attribute 'get_config'
ERROR tests/test_performance_enhanced.py::TestPerformanceOptimizedProcessor::test_processor_initialization - KeyError: 'performance'
ERROR tests/test_performance_enhanced.py::TestPerformanceOptimizedProcessor::test_optimized_processing_session - KeyError: 'performance'
ERROR tests/test_performance_enhanced.py::TestPerformanceOptimizedProcessor::test_parallel_file_processing - KeyError: 'performance'
ERROR tests/test_performance_enhanced.py::TestPerformanceOptimizedProcessor::test_empty_files_processing - KeyError: 'performance'
ERROR tests/test_performance_enhanced.py::TestPerformanceOptimizedProcessor::test_single_file_processing_with_caching - KeyError: 'performance'
ERROR tests/test_performance_optimizer.py::TestParallelProcessor::test_determine_processing_mode - KeyError: 'performance'
ERROR tests/test_performance_optimizer.py::TestParallelProcessor::test_process_single_document - KeyError: 'performance'
ERROR tests/test_performance_optimizer.py::TestParallelProcessor::test_process_batch_sequential - KeyError: 'performance'
ERROR tests/test_performance_optimizer.py::TestParallelProcessor::test_process_batch_parallel_threads - KeyError: 'performance'
ERROR tests/test_performance_optimizer.py::TestParallelProcessor::test_execute_task - KeyError: 'performance'
ERROR tests/test_performance_optimizer.py::TestParallelProcessor::test_execute_task_with_error - KeyError: 'performance'
ERROR tests/test_performance_optimizer.py::TestBatchEngine::test_submit_batch - KeyError: 'performance'
ERROR tests/test_performance_optimizer.py::TestBatchEngine::test_process_next_batch - KeyError: 'performance'
ERROR tests/test_performance_optimizer.py::TestBatchEngine::test_get_queue_stats - KeyError: 'performance'
ERROR tests/test_performance_optimizer.py::TestBatchEngine::test_process_empty_queue - KeyError: 'performance'
ERROR tests/test_training_data_collector.py::TestTrainingDataStorage::test_storage_initialization - PermissionError: [WinError 32] The process cannot access the file because it is being used by another process: 'C:\\Users\\tomas\\AppData\\Local\\Temp\\tmpv1rxrvwk\\training_data.db'
ERROR tests/adaptive/test_coordinator.py::test_initialization - AttributeError: <module 'app.core.adaptive.coordinator' from 'C:\\Users\\tomas\\Desktop\\0001 DUOMENU ANALITIKA\\038_AnonymPDF\\app\\core\\adaptive\\coordinator.py'> does not have the ...
ERROR tests/adaptive/test_coordinator.py::test_process_feedback_and_learn_cycle - AttributeError: <module 'app.core.adaptive.coordinator' from 'C:\\Users\\tomas\\Desktop\\0001 DUOMENU ANALITIKA\\038_AnonymPDF\\app\\core\\adaptive\\coordinator.py'> does not have the ...
ERROR tests/adaptive/test_coordinator.py::test_process_feedback_with_no_new_pii - AttributeError: <module 'app.core.adaptive.coordinator' from 'C:\\Users\\tomas\\Desktop\\0001 DUOMENU ANALITIKA\\038_AnonymPDF\\app\\core\\adaptive\\coordinator.py'> does not have the ...
ERROR tests/adaptive/test_coordinator.py::test_ab_testing_integration - AttributeError: <module 'app.core.adaptive.coordinator' from 'C:\\Users\\tomas\\Desktop\\0001 DUOMENU ANALITIKA\\038_AnonymPDF\\app\\core\\adaptive\\coordinator.py'> does not have the ...
ERROR tests/adaptive/test_coordinator.py::test_evaluate_and_log_ab_test - AttributeError: <module 'app.core.adaptive.coordinator' from 'C:\\Users\\tomas\\Desktop\\0001 DUOMENU ANALITIKA\\038_AnonymPDF\\app\\core\\adaptive\\coordinator.py'> does not have the ...
ERROR tests/adaptive/test_coordinator.py::test_close_method - AttributeError: <module 'app.core.adaptive.coordinator' from 'C:\\Users\\tomas\\Desktop\\0001 DUOMENU ANALITIKA\\038_AnonymPDF\\app\\core\\adaptive\\coordinator.py'> does not have the ...
ERROR tests/system/test_adaptive_workflow.py::test_fixture_creation - TypeError: QualityAnalyzer.__init__() got an unexpected keyword argument 'storage_path'
ERROR tests/system/test_adaptive_workflow.py::test_feedback_creates_pattern_and_overrides_prediction - TypeError: QualityAnalyzer.__init__() got an unexpected keyword argument 'storage_path'
ERROR tests/system/test_adaptive_workflow.py::test_ab_testing_full_lifecycle - TypeError: QualityAnalyzer.__init__() got an unexpected keyword argument 'storage_path'
FAILED tests/test_analytics_engine.py::TestQualityAnalyzer::test_add_detection_result - AttributeError: 'QualityAnalyzer' object has no attribute 'add_detection_result'
FAILED tests/test_analytics_engine.py::TestQualityAnalyzer::test_add_detection_result_with_ground_truth - AttributeError: 'QualityAnalyzer' object has no attribute 'add_detection_result'
FAILED tests/test_analytics_engine.py::TestQualityAnalyzer::test_analyze_detection_quality_single_category - AttributeError: 'QualityAnalyzer' object has no attribute 'add_detection_result'
FAILED tests/test_analytics_engine.py::TestQualityAnalyzer::test_analyze_detection_quality_multiple_categories - AttributeError: 'QualityAnalyzer' object has no attribute 'add_detection_result'
FAILED tests/test_analytics_engine.py::TestQualityAnalyzer::test_analyze_detection_quality_with_document_type_filter - AttributeError: 'QualityAnalyzer' object has no attribute 'add_detection_result'
FAILED tests/test_analytics_engine.py::TestQualityAnalyzer::test_analyze_detection_quality_with_ground_truth - AttributeError: 'QualityAnalyzer' object has no attribute 'add_detection_result'
FAILED tests/test_analytics_engine.py::TestQualityAnalyzer::test_detect_quality_issues_low_confidence - AttributeError: 'QualityAnalyzer' object has no attribute 'add_detection_result'
FAILED tests/test_analytics_engine.py::TestQualityAnalyzer::test_detect_quality_issues_performance_degradation - AttributeError: 'QualityAnalyzer' object has no attribute 'add_detection_result'
FAILED tests/test_analytics_engine.py::TestQualityAnalyzer::test_detect_quality_issues_high_false_positive - AttributeError: 'QualityAnalyzer' object has no attribute 'add_detection_result'
FAILED tests/test_analytics_engine.py::TestQualityAnalyzer::test_get_quality_report_empty - AttributeError: 'QualityAnalyzer' object has no attribute 'get_quality_report'
FAILED tests/test_analytics_engine.py::TestQualityAnalyzer::test_get_quality_report_with_data - AttributeError: 'QualityAnalyzer' object has no attribute 'add_detection_result'
FAILED tests/test_analytics_engine.py::TestQualityAnalyzer::test_get_improvement_suggestions_no_issues - AttributeError: 'QualityAnalyzer' object has no attribute 'get_improvement_suggestions'
FAILED tests/test_analytics_engine.py::TestQualityAnalyzer::test_get_improvement_suggestions_with_issues - AttributeError: 'QualityAnalyzer' object has no attribute 'quality_issues'
FAILED tests/test_analytics_engine.py::TestQualityAnalyzer::test_storage_integration - AttributeError: 'QualityAnalyzer' object has no attribute 'add_detection_result'
FAILED tests/test_analytics_engine.py::TestQualityAnalyzer::test_get_quality_trends_insufficient_data - AttributeError: 'QualityAnalyzer' object has no attribute 'get_quality_trends'
FAILED tests/test_analytics_engine.py::TestQualityAnalyzer::test_get_quality_trends_valid_metric - AttributeError: 'QualityAnalyzer' object has no attribute 'storage_path'
FAILED tests/test_analytics_engine.py::TestQualityAnalyzer::test_get_quality_trends_declining - AttributeError: 'QualityAnalyzer' object has no attribute 'storage_path'
FAILED tests/test_analytics_engine.py::TestQualityAnalyzer::test_get_quality_trends_invalid_metric - AttributeError: 'QualityAnalyzer' object has no attribute 'get_quality_trends'
FAILED tests/test_analytics_engine.py::TestQualityAnalyzer::test_thread_safety - sqlite3.OperationalError: no such table: detection_results
FAILED tests/test_analytics_engine.py::TestQualityAnalyzer::test_config_integration - AttributeError: 'QualityAnalyzer' object has no attribute 'storage_path'
FAILED tests/test_analytics_engine.py::TestQualityAnalyzer::test_ml_integration_compatibility - AttributeError: 'QualityAnalyzer' object has no attribute 'add_detection_result'
FAILED tests/test_analytics_engine.py::TestQualityAnalyzer::test_performance_impact - AttributeError: 'QualityAnalyzer' object has no attribute 'add_detection_result'
FAILED tests/test_analytics_engine.py::TestQualityInsightsGenerator::test_generate_pattern_insights_empty - AttributeError: 'QualityInsightsGenerator' object has no attribute 'generate_pattern_insights'
FAILED tests/test_analytics_engine.py::TestQualityInsightsGenerator::test_generate_pattern_insights_with_data - AttributeError: 'QualityAnalyzer' object has no attribute 'add_detection_result'
FAILED tests/test_analytics_engine.py::TestQualityInsightsGenerator::test_generate_model_insights_insufficient_data - AttributeError: 'QualityInsightsGenerator' object has no attribute 'generate_model_insights'
FAILED tests/test_analytics_engine.py::TestQualityInsightsGenerator::test_generate_model_insights_excellent_model - AttributeError: 'QualityAnalyzer' object has no attribute 'add_detection_result'
FAILED tests/test_analytics_engine.py::TestQualityInsightsGenerator::test_generate_model_insights_needs_improvement - AttributeError: 'QualityAnalyzer' object has no attribute 'add_detection_result'
FAILED tests/test_analytics_engine.py::TestQualityInsightsGenerator::test_generate_report_with_data - AttributeError: 'QualityAnalyzer' object has no attribute 'add_detection_result'
FAILED tests/test_analytics_engine.py::TestAnalyticsEngineIntegration::test_full_analysis_workflow - AttributeError: 'TestAnalyticsEngineIntegration' object has no attribute 'create_mock_detection_result'
FAILED tests/test_config_manager.py::TestConfigManager::test_configuration_validation - assert False is True
FAILED tests/test_feedback_system.py::TestFeedbackSystemIntegration::test_feedback_submission_and_processing_flow - AttributeError: <app.core.training_data.TrainingDataCollector object at 0x000001F5ACFCDC90> does not have the attribute 'save_training_examples'
FAILED tests/test_intelligent_cache.py::TestIntelligentCache::test_comprehensive_stats - KeyError: 'general'
FAILED tests/test_intelligent_cache.py::TestConcurrency::test_thread_safety - KeyError: 'general'
FAILED tests/test_memory_optimizer.py::TestIntegration::test_memory_threshold_handling - AssertionError: MemoryMonitor should log a warning for high memory usage
FAILED tests/test_morning_ses5_improvements.py::TestMorningSes5Patterns::test_enhanced_car_plate_contextual_pattern - AttributeError: 'PDFProcessor' object has no attribute 'patterns'
FAILED tests/test_morning_ses5_improvements.py::TestMorningSes5Patterns::test_enhanced_car_plate_enhanced_pattern - AttributeError: 'PDFProcessor' object has no attribute 'patterns'
FAILED tests/test_morning_ses5_improvements.py::TestMorningSes5Patterns::test_lithuanian_name_all_caps_pattern - AttributeError: 'PDFProcessor' object has no attribute 'patterns'
FAILED tests/test_morning_ses5_improvements.py::TestMorningSes5Patterns::test_lithuanian_name_contextual_pattern - AttributeError: 'PDFProcessor' object has no attribute 'patterns'
FAILED tests/test_morning_ses5_improvements.py::TestMorningSes5Patterns::test_lithuanian_name_contextual_caps_pattern - AttributeError: 'PDFProcessor' object has no attribute 'patterns'
FAILED tests/test_morning_ses5_improvements.py::TestMorningSes5Patterns::test_lithuanian_address_flexible_pattern - AttributeError: 'PDFProcessor' object has no attribute 'patterns'
FAILED tests/test_morning_ses5_improvements.py::TestMorningSes5Patterns::test_lithuanian_personal_code_contextual_pattern - AttributeError: 'PDFProcessor' object has no attribute 'patterns'
FAILED tests/test_morning_ses5_improvements.py::TestMorningSes5Integration::test_comprehensive_lithuanian_document_processing - KeyError: 'names'
FAILED tests/test_morning_ses5_improvements.py::TestMorningSes5Integration::test_anti_overredaction_in_technical_context - KeyError: 'names'
FAILED tests/test_pdf_processor.py::test_find_personal_info - AttributeError: <app.services.pdf_processor.PDFProcessor object at 0x000001F5D04619D0> has no attribute 'patterns'
FAILED tests/test_pdf_processor.py::test_generate_redaction_report - AttributeError: <app.services.pdf_processor.PDFProcessor object at 0x000001F5D04619D0> has no attribute 'patterns'
FAILED tests/test_pdf_processor.py::test_process_pdf_failure_on_invalid_content - AssertionError: assert 'Failed to open document' in 'An exception occurred during anonymization'
FAILED tests/test_performance.py::TestPerformanceIntegration::test_get_performance_report - KeyError: 'performance'
FAILED tests/test_performance_enhanced.py::TestGlobalFunctions::test_get_performance_report - TypeError: 'dict' object does not support the context manager protocol
FAILED tests/test_performance_enhanced.py::TestGlobalFunctions::test_get_parallel_processor - KeyError: 'performance'
FAILED tests/test_performance_enhanced.py::TestGlobalFunctions::test_performance_report_with_optimizers - KeyError: 'performance'
FAILED tests/test_performance_enhanced.py::TestIntegration::test_end_to_end_parallel_processing - KeyError: 'performance'
FAILED tests/test_performance_enhanced.py::TestIntegration::test_concurrent_metric_collection - KeyError: 'performance'
FAILED tests/test_performance_enhanced.py::TestIntegration::test_performance_under_load - KeyError: 'performance'
FAILED tests/test_performance_optimizer.py::TestGlobalInstances::test_get_parallel_processor - KeyError: 'performance'
FAILED tests/test_performance_optimizer.py::TestGlobalInstances::test_get_batch_engine - KeyError: 'performance'
FAILED tests/test_performance_optimizer.py::TestIntegration::test_end_to_end_processing - KeyError: 'performance'
FAILED tests/test_performance_optimizer.py::TestIntegration::test_performance_improvement_simulation - KeyError: 'performance'
FAILED tests/test_real_time_monitor.py::TestAnomalyDetector::test_alert_threshold_integration - assert 0 > 0
FAILED tests/test_real_time_monitor.py::TestRealTimeMonitor::test_ml_monitor_callback_functionality - AssertionError: assert 0 == 1
FAILED tests/test_real_time_monitor.py::TestRealTimeMonitor::test_alert_callback_system - TypeError: Object of type Mock is not JSON serializable
FAILED tests/test_training_data_collector.py::TestTrainingDataStorage::test_save_and_load_training_examples - TypeError: create_dummy_example() got an unexpected keyword argument 'source'
FAILED tests/test_training_data_collector.py::TestTrainingDataStorage::test_get_dataset_stats_empty - AttributeError: 'NoneType' object has no attribute 'total_samples'
FAILED tests/test_training_data_collector.py::TestTrainingDataCollector::test_get_balanced_training_set_with_data - assert 6 == 13
FAILED tests/test_validation_utils.py::TestPersonNameValidation::test_length_validation - AssertionError: assert not True
FAILED tests/adaptive/test_ab_testing.py::TestABTestManager::test_record_and_evaluate_metrics_variant_wins - KeyError: 'winner'
FAILED tests/adaptive/test_online_learner.py::TestOnlineLearner::test_retrain_model_saves_examples_and_triggers_retraining - AttributeError: 'OnlineLearner' object has no attribute 'retrain_model'
FAILED tests/adaptive/test_online_learner.py::TestOnlineLearner::test_retrain_model_saves_examples_but_skips_retraining - AttributeError: 'OnlineLearner' object has no attribute 'retrain_model'
FAILED tests/adaptive/test_pattern_learner.py::TestPatternLearner::test_discover_and_validate_patterns - assert 0 == 1
=================================================================== 68 failed, 280 passed, 39 errors in 95.17s (0:01:35) ===================================================================
(venv) PS C:\Users\tomas\Desktop\0001 DUOMENU ANALITIKA\038_AnonymPDF>